<?xml version='1.0' ?>
<sdf version='1.4'>
  <model name='Doris'>
	<static>true</static>
	 <link name='cuerpo'> 
          <pose> 0 0 0.222 0 0 0 </pose>
            <collision name='cuerpo_collision'>
              <geometry>
                <cylinder>
                  <radius>.30</radius>
                  <length>.33</length>
                </cylinder>
              </geometry>
              <surface>
 		<friction>
 			<ode>
 			<mu>0</mu>
 			<mu2>0</mu2>
 			<slip1>1.0</slip1>
 			<slip2>1.0</slip2>
 			</ode>
 		</friction>
	     </surface>
            </collision>
            <visual name='cuerpo_visual'>
              <geometry>
                <cylinder>
                 <radius>.30</radius>
                 <length>.33</length>
                </cylinder>
              </geometry>
            </visual>
          </link>
	  <!--<link name= 'head'>
	    <pose>0 0 0.4 0 0 0</pose>
           <collision name ='head_collision'>
	    <geometry>
                <sphere>
                 <radius>.1</radius>
                </sphere>
            </geometry> 
           </collision>
           <visual name = 'head_visual'>
            <geometry>
                <sphere>
                 <radius>.1</radius>
                </sphere>
            </geometry> 
           </visual>
           </link> -->
	   <link name="left_wheel">
             <pose>0 0.15 0.05 0 1.5707 1.5707</pose>
              <collision name="collision">
               <geometry>
                <cylinder>
                 <radius>.05</radius>
                 <length>.05</length>
                </cylinder>
               </geometry>
              </collision>
              <visual name="visual">
               <geometry>
                <cylinder>
                 <radius>.05</radius>
                  <length>.05</length>
                </cylinder>
               </geometry>
              </visual>
           </link>
           <link name="right_wheel">
        <pose>0 -0.15 0.05 0 1.5707 1.5707</pose>
        <collision name="collisionr">
          <geometry>
            <cylinder>
              <radius>.05</radius>
              <length>.05</length>
            </cylinder>
          </geometry>
        </collision>
        <visual name="visualr">
          <geometry>
            <cylinder>
              <radius>.05</radius>
              <length>.05</length>
            </cylinder>
          </geometry>
        </visual>
      </link>
     
     <link name="mastil">
          <pose> 0 0 0.85 0 0 0 </pose>
          <collision name='mastil_collision'>
              <geometry>
                <box>
                  <size> 0.1 0.1 0.95</size>
                </box> 
              </geometry>
          </collision>
          <visual name="mastil_visual">
              <geometry>
                <box>
                  <size> 0.1 0.1 0.95</size>
                </box> 
              </geometry>
           </visual>
          </link>
      <link name='plataforma' >
         <pose> 0 0 1.3375 0 0 0 </pose>
         <collision name= 'plataforma_collision'>
         <geometry>
              <cylinder>
                  <radius> 0.1 </radius>
                  <length> 0.025 </length>
              </cylinder>
          </geometry>
         </collision>
         <visual name= 'plataforma_visual'>
           <geometry>
              <cylinder>
                  <radius> 0.1 </radius>
                  <length> 0.025 </length>
              </cylinder>
          </geometry>
         </visual>
        </link>
        <link name= 'contrapeso'>
	<inertial>
        	<mass>0.040046547</mass>
         </inertial>
         <pose>-0.25 0 0.397 0 0 0</pose>
         <collision name= 'contrapeso_collision'>
         <geometry>
              <cylinder>
                  <radius> 0.03 </radius>
                  <length> 0.025 </length>
              </cylinder>
          </geometry>
         </collision>
         <visual name= 'contrapeso_visual'>
           <geometry>
              <cylinder>
                  <radius> 0.03 </radius>
                  <length> 0.025 </length>
              </cylinder>
          </geometry>
         </visual>
        </link>
        <joint name="cas1j" type="fixed">
          <parent>cuerpo</parent>
           <child>cas1::link</child>
          <pose> -0.2 -0.15 0.05 0 0 0  </pose>
	</joint>
        <joint name="cas2j" type="fixed">
          <parent>cuerpo</parent>
           <child>cas2::link</child>
           <pose>  0.2 -0.15 0.05 0 0 0  </pose>
	</joint>
        <joint name="cas3j" type="fixed">
          <parent>cuerpo</parent>
           <child>cas3::link</child>
          <pose>  -0.2 0.15 0.05 0 0 0  </pose>
	</joint>
        <joint name="cas4j" type="fixed">
          <parent>cuerpo</parent>
           <child>cas4::link</child>
         <pose> 0.2 0.15 0.05 0 0 0  </pose>
	</joint>
        <joint type='revolute' name='contrap_cuerpo'>
            <pose>-0.1 0 0.397 0 0 0</pose>
            <child>contrapeso</child>
           <parent>cuerpo</parent> 
            <axis>
             <xyz>0 0 1</xyz>
             <limit>
               <upper>0</upper>
               <lower>0</lower>
             </limit>
           </axis>
        </joint>
        <joint type='revolute' name='mastil_plat'>
            <pose> -0.2 0.2 1.325 0 0 0 </pose>
            <child>plataforma</child>
           <parent>mastil</parent> 
            <axis>
             <xyz>0 0 1</xyz>
             <limit>
               <upper>0</upper>
               <lower>0</lower>
             </limit>
           </axis>
        </joint>
        <joint type='revolute' name='plat_cam1'>
            <pose> 0.1 0 1.35 0 0 0 </pose>
            <child>Camara::linkCam1</child>
           <parent>plataforma</parent> 
            <axis>
             <xyz>0 0 1</xyz>
             <limit>
               <upper>0</upper>
               <lower>0</lower>
             </limit>
           </axis>
        </joint>
        <joint type='revolute' name='plat_cam2'>
           <pose>-0.1 0.173 1.35 0 0 2.093</pose>
            <child>Camara2::linkCam2</child>
           <parent>plataforma</parent> 
            <axis>
             <xyz>0 0 1</xyz>
             <limit>
               <upper>0</upper>
               <lower>0</lower>
             </limit>
           </axis>
        </joint>
        <joint type='revolute' name='plat_cam3'>
           <pose>-0.1 -0.173 1.35 0 0 -2.093</pose>
            <child>Camara3::linkCam3</child>
           <parent>plataforma</parent> 
            <axis>
             <xyz>0 0 1</xyz>
             <limit>
               <upper>0</upper>
               <lower>0</lower>
             </limit>
           </axis>
        </joint>
        <joint type="revolute" name="mastil_cuerpo">
           <pose>-0.2 0.2 0.4 0 0 0 </pose>
           <child>mastil</child>
           <parent>cuerpo</parent>
           <axis>
             <xyz>0 0 1</xyz>
             <limit>
               <upper>0</upper>
               <lower>0</lower>
             </limit>
           </axis>
        </joint>
	<joint type="revolute" name="left_axis">
        <pose>0 0 -0.05 0 0 0</pose>
        <child>left_wheel</child>
        <parent>cuerpo</parent>
        <axis>
          <xyz>0 1 0</xyz>
        </axis>
      </joint>
      <joint type="revolute" name="right_axis">
        <pose>0 0 0.05 0 0 0</pose>
        <child>right_wheel</child>
        <parent>cuerpo</parent>
        <axis>
          <xyz>0 1 0</xyz>
        </axis>
      </joint>
    <include>
      <uri>model://Hokuyo_Laser</uri>
      <pose>0.1 0 0.397 0 0 0</pose>
    </include>
    <joint name="hokuyo_joint" type="revolute">
      <pose>0.1 0 0.397 0 0 0</pose>
      <child>hokuyo::link</child>
      <parent>cuerpo</parent>
      <axis>
        <xyz>0 0 1</xyz>
        <limit>
          <upper>0</upper>
          <lower>0</lower>
        </limit>
      </axis>
   </joint>
   
 <include>
     <uri>model://Camara</uri>
     <pose> 0.1 0 1.4 0 0 0</pose>
  </include>
  <include>
     <uri>model://Camara2</uri>
     <pose> -0.05 0.08660254 1.4 0 0 2.093</pose>
  </include>
  <include>
     <uri>model://Camara3</uri>
     <pose>-0.05 -0.08660254 1.4 0 0 -2.093</pose>
  </include>
  <include>
     <uri>model://Caster_Wheel</uri>
      <name>cas1</name>
     <pose>  -0.15 -0.15 0.05 0 0 0  </pose>
  </include>
   <include>
     <uri>model://Caster_Wheel</uri>
     <name>cas2</name>
     <pose>  0.15 -0.15 0.05 0 0 0  </pose>
  </include>
  <include>
     <uri>model://Caster_Wheel</uri>
     <name>cas3</name>
     <pose>  -0.15 0.15 0.05 0 0 0  </pose>
  </include>
   <include>
     <uri>model://Caster_Wheel</uri>
     <name>cas4</name>
     <pose> 0.15 0.15 0.05 0 0 0  </pose>
  </include>
  <plugin name="differential_drive_controller" filename="libgazebo_ros_diff_drive.so">
  <alwaysOn>true</alwaysOn>
  <updateRate>20</updateRate>
  <leftJoint>right_axis</leftJoint>
  <rightJoint>left_axis</rightJoint>
  <wheelSeparation>0.1</wheelSeparation>
  <wheelDiameter>0.1</wheelDiameter>
  <torque>20</torque>
  <commandTopic>cmd_vel</commandTopic>
  <odometryTopic>odom</odometryTopic>
  <odometryFrame>odom</odometryFrame>
  <robotBaseFrame>base_footprint</robotBaseFrame>
  <legacyMode>true</legacyMode>
  </plugin>
  </model>
</sdf>
